2017-09-24 17:55:23,763 INFO org.apache.hadoop.yarn.server.resourcemanager.scheduler.capacity.CapacityScheduler: Application Attempt appattempt_1506273945421_0004_000001 is done. finalState=KILLED
2017-09-24 17:55:23,763 INFO org.apache.hadoop.yarn.server.resourcemanager.scheduler.AppSchedulingInfo: Application application_1506273945421_0004 requests cleared
2017-09-24 17:55:23,764 DEBUG org.apache.hadoop.yarn.server.resourcemanager.scheduler.capacity.LeafQueue: application application_1506273945421_0001 AMResource <memory:2048, vCores:1> maxAMResourcePerQueuePercent 0.1 amLimit <memory:0, vCores:0> lastClusterResource <memory:0, vCores:0> amIfStarted <memory:2048, vCores:1> AM node-partition name 
2017-09-24 17:55:23,764 WARN org.apache.hadoop.yarn.server.resourcemanager.scheduler.capacity.LeafQueue: maximum-am-resource-percent is insufficient to start a single application in queue, it is likely set too low. skipping enforcement to allow at least one application to start
2017-09-24 17:55:23,764 WARN org.apache.hadoop.yarn.server.resourcemanager.scheduler.capacity.LeafQueue: maximum-am-resource-percent is insufficient to start a single application in queue for user, it is likely set too low. skipping enforcement to allow at least one application to start
2017-09-24 17:55:23,764 INFO org.apache.hadoop.yarn.server.resourcemanager.scheduler.capacity.LeafQueue: Application application_1506273945421_0001 from user: ubuntu activated in queue: default
2017-09-24 17:55:23,764 DEBUG org.apache.hadoop.yarn.server.resourcemanager.scheduler.capacity.LeafQueue: application application_1506273945421_0002 AMResource <memory:2048, vCores:1> maxAMResourcePerQueuePercent 0.1 amLimit <memory:0, vCores:0> lastClusterResource <memory:0, vCores:0> amIfStarted <memory:4096, vCores:2> AM node-partition name 
2017-09-24 17:55:23,764 DEBUG org.apache.hadoop.yarn.server.resourcemanager.scheduler.capacity.LeafQueue: Not activating application application_1506273945421_0002 as  amIfStarted: <memory:4096, vCores:2> exceeds amLimit: <memory:0, vCores:0>
2017-09-24 17:55:23,764 DEBUG org.apache.hadoop.yarn.server.resourcemanager.scheduler.capacity.LeafQueue: application application_1506273945421_0003 AMResource <memory:2048, vCores:1> maxAMResourcePerQueuePercent 0.1 amLimit <memory:0, vCores:0> lastClusterResource <memory:0, vCores:0> amIfStarted <memory:4096, vCores:2> AM node-partition name 
2017-09-24 17:55:23,764 DEBUG org.apache.hadoop.yarn.server.resourcemanager.scheduler.capacity.LeafQueue: Not activating application application_1506273945421_0003 as  amIfStarted: <memory:4096, vCores:2> exceeds amLimit: <memory:0, vCores:0>
2017-09-24 17:55:23,764 INFO org.apache.hadoop.yarn.server.resourcemanager.scheduler.capacity.LeafQueue: Application removed - appId: application_1506273945421_0004 user: ubuntu queue: default #user-pending-applications: 2 #user-active-applications: 1 #queue-pending-applications: 2 #queue-active-applications: 1
2017-09-24 17:55:23,765 INFO org.apache.hadoop.yarn.server.resourcemanager.scheduler.capacity.ParentQueue: Application removed - appId: application_1506273945421_0004 user: ubuntu leaf-queue of parent: root #applications: 3
2017-09-24 17:55:23,779 DEBUG org.apache.hadoop.yarn.server.resourcemanager.scheduler.AbstractYarnScheduler: Request for appInfo of unknown attempt appattempt_1506273945421_0004_000001
